Workbook

Sheet Sheet1
B1: =_xll.PTreeNodeDecision(treeCalc_1!$F$2,2) -> FALSE | C1: =_xll.PTreeNodeProbability(treeCalc_1!$F$2,2) -> 0 | K1: Risk Tolerance | L1: 43.289373
B2: 20 | C2: =_xll.PTreeNodeValue(treeCalc_1!$F$2,2) -> 20
B3: Decision
B4: =_xll.PTreeNodeValue(treeCalc_1!$F$2,1) -> 50.04786
E5: 0.85 | F5: =_xll.PTreeNodeProbability(treeCalc_1!$F$2,13) -> 0.10693
E6: 125 | F6: =_xll.PTreeNodeValue(treeCalc_1!$F$2,13) -> 125
D7: 0.68 | E7: Ion Engine
D8: 0 | E8: =_xll.PTreeNodeValue(treeCalc_1!$F$2,7) -> 104
E9: 0.15 | F9: =_xll.PTreeNodeProbability(treeCalc_1!$F$2,14) -> 0.01887
E10: -15 | F10: =_xll.PTreeNodeValue(treeCalc_1!$F$2,14) -> -15
C11: 0.185 | D11: Contract/settlement outcomes
C12: 0 | D12: =_xll.PTreeNodeValue(treeCalc_1!$F$2,4) -> 65.92
E13: 0.85 | F13: =_xll.PTreeNodeProbability(treeCalc_1!$F$2,15) -> 0.05032
E14: -15 | F14: =_xll.PTreeNodeValue(treeCalc_1!$F$2,15) -> -15
D15: 0.32 | E15: Ion Engine
D16: 0 | E16: =_xll.PTreeNodeValue(treeCalc_1!$F$2,8) -> -15
E17: 0.15 | F17: =_xll.PTreeNodeProbability(treeCalc_1!$F$2,16) -> 0.00888
E18: -15 | F18: =_xll.PTreeNodeValue(treeCalc_1!$F$2,16) -> -15
B19: =_xll.PTreeNodeDecision(treeCalc_1!$F$2,3) -> TRUE | C19: Production cost uncertainty
B20: 0 | C20: =_xll.PTreeNodeValue(treeCalc_1!$F$2,3) -> 50.04786
E21: 0.85 | F21: =_xll.PTreeNodeProbability(treeCalc_1!$F$2,17) -> 0.36414
E22: 100 | F22: =_xll.PTreeNodeValue(treeCalc_1!$F$2,17) -> 100
D23: 0.68 | E23: Technical success/failure
D24: 0 | E24: =_xll.PTreeNodeValue(treeCalc_1!$F$2,9) -> 82.3
E25: 0.15 | F25: =_xll.PTreeNodeProbability(treeCalc_1!$F$2,18) -> 0.06426
E26: -18 | F26: =_xll.PTreeNodeValue(treeCalc_1!$F$2,18) -> -18
C27: 0.63 | D27: Contract/settlement outcomes
C28: 0 | D28: =_xll.PTreeNodeValue(treeCalc_1!$F$2,5) -> 50.204
E29: 0.85 | F29: =_xll.PTreeNodeProbability(treeCalc_1!$F$2,19) -> 0.17136
E30: -18 | F30: =_xll.PTreeNodeValue(treeCalc_1!$F$2,19) -> -18
D31: 0.32 | E31: Technical success/failure
D32: 0 | E32: =_xll.PTreeNodeValue(treeCalc_1!$F$2,10) -> -18
E33: 0.15 | F33: =_xll.PTreeNodeProbability(treeCalc_1!$F$2,20) -> 0.03024
E34: -18 | F34: =_xll.PTreeNodeValue(treeCalc_1!$F$2,20) -> -18
E35: 0.85 | F35: =_xll.PTreeNodeProbability(treeCalc_1!$F$2,21) -> 0.10693
E36: 75 | F36: =_xll.PTreeNodeValue(treeCalc_1!$F$2,21) -> 75
D37: 0.68 | E37: Technical success/failure
D38: 0 | E38: =_xll.PTreeNodeValue(treeCalc_1!$F$2,11) -> 60.3
E39: 0.15 | F39: =_xll.PTreeNodeProbability(treeCalc_1!$F$2,22) -> 0.01887
E40: -23 | F40: =_xll.PTreeNodeValue(treeCalc_1!$F$2,22) -> -23
...

Sheet treeCalc_1
A1: Name | B1: Interplants | E1: Ptree1 Compatibility | F1: 3 | H1: Output Label | K1: R-Value Ref. | L1: =Sheet1!$L$1 -> 43.289373
A2: SheetRef | B2: =Sheet1!#REF! -> #REF! | E2: Eval. Function | F2: =_xll.PTreeEvaluate5(B3,$L$11:$L$34,$J$11:$J$34,$K$11:$K$34,$N$11:$N$34,$G$11:$G$34,,L1) -> 488833
A3: GenInfo | B3: 0,1,1,0,0,Exponential, 0,0,-1,0,-1,-1,.0001 | E3: Creation Version | F3: 8.12.0 | H3: Output Value NF | I3: <NF>
A4: Def. Link | B4: = | E4: Required Version | F4: 5.0.0 | H4: Output Prob NF | I4: Automatic
A5: EXT REFS | B5: 0 | E5: Recommended Version | F5: 5.0.0 | H5: Input Value NF | I5: <NF>
A6: Def. Form | E6: Last Modified By Version | F6: 8.12.0 | H6: Input Prob NF | I6: Automatic
A7: Calc Macro | E7: Model GUID | F7: 239D207A
A8: Highest# | B8: 24
A10: Anchor Cell | B10: Branch Name | C10: bformtype | D10: valformula | E10: pbformula | F10: distribution | G10: cumPayoffFunction | H10: link | I10: ENDNODEFORMULA | J10: VAL | K10: PB | L10: GenInfo | M10: IntRefs | N10: RefRefs | O10: NodeNames | P10: Collapsed
A11: =Sheet1!$B$4 -> 50.04786 | B11: =B1 -> Interplants | C11: 0 | I11: DEFAULT | J11: =Sheet1!$A$4 -> 0 | K11: =Sheet1!$A$3 -> 0 | L11: 2,0,0,2,2,3,0,0,0 | M11: 0 | O11: =Sheet1!$B$3 -> Decision | P11: FALSE
A12: =Sheet1!$C$2 -> 20 | B12: Sell | C12: 0 | H12: DEFAULT | I12: DEFAULT | J12: =Sheet1!$B$2 -> 20 | L12: 4,0,0,0,1,0,0 | M12: 0 | P12: FALSE
A13: =Sheet1!$C$20 -> 50.04786 | B13: Continue Operation | C13: 0 | I13: DEFAULT | J13: =Sheet1!$B$20 -> 0 | L13: 1,0,0,3,4,5,6,1,0,0 | M13: 0 | O13: =Sheet1!$C$19 -> Production cost uncertainty | P13: FALSE
A14: =Sheet1!$D$12 -> 65.92 | B14: Inexperience | C14: 0 | I14: DEFAULT | J14: =Sheet1!$C$12 -> 0 | K14: =Sheet1!$C$11 -> 0.185 | L14: 1,0,0,2,7,8,3,0,0 | M14: 0 | O14: =Sheet1!$D$11 -> Contract/settlement outcomes | P14: FALSE
A15: =Sheet1!$D$28 -> 50.204 | B15: Moderate | C15: 0 | I15: DEFAULT | J15: =Sheet1!$C$28 -> 0 | K15: =Sheet1!$C$27 -> 0.63 | L15: 1,0,0,2,9,10,3,0,0 | M15: 0 | O15: =Sheet1!$D$27 -> Contract/settlement outcomes | P15: FALSE
A16: =Sheet1!$D$42 -> 33.644 | B16: Costly | C16: 0 | I16: DEFAULT | J16: =Sheet1!$C$42 -> 0 | K16: =Sheet1!$C$41 -> 0.185 | L16: 1,0,0,2,11,12,3,0,0 | M16: 0 | O16: =Sheet1!$D$41 -> Contract/settlement outcomes | P16: FALSE
A17: =Sheet1!$E$8 -> 104 | B17: Agreement | C17: 0 | I17: DEFAULT | J17: =Sheet1!$D$8 -> 0 | K17: =Sheet1!$D$7 -> 0.68 | L17: 1,0,0,2,13,14,4,0,0 | M17: 0 | O17: =Sheet1!$E$7 -> Ion Engine | P17: FALSE
A18: =Sheet1!$E$16 -> -15 | B18: Dispute | C18: 0 | I18: DEFAULT | J18: =Sheet1!$D$16 -> 0 | K18: =Sheet1!$D$15 -> 0.32 | L18: 1,0,0,2,15,16,4,0,0 | M18: 0 | O18: =Sheet1!$E$15 -> Ion Engine | P18: FALSE
A19: =Sheet1!$E$24 -> 82.3 | B19: Agreement | C19: 0 | I19: DEFAULT | J19: =Sheet1!$D$24 -> 0 | K19: =Sheet1!$D$23 -> 0.68 | L19: 1,0,0,2,17,18,5,0,0 | M19: 0 | O19: =Sheet1!$E$23 -> Technical success/failure | P19: FALSE
A20: =Sheet1!$E$32 -> -18 | B20: Dispute | C20: 0 | I20: DEFAULT | J20: =Sheet1!$D$32 -> 0 | K20: =Sheet1!$D$31 -> 0.32 | L20: 1,0,0,2,19,20,5,0,0 | M20: 0 | O20: =Sheet1!$E$31 -> Technical success/failure | P20: FALSE
A21: =Sheet1!$E$38 -> 60.3 | B21: Agreement | C21: 0 | I21: DEFAULT | J21: =Sheet1!$D$38 -> 0 | K21: =Sheet1!$D$37 -> 0.68 | L21: 1,0,0,2,21,22,6,0,0 | M21: 0 | O21: =Sheet1!$E$37 -> Technical success/failure | P21: FALSE
A22: =Sheet1!$E$46 -> -23 | B22: Dispute | C22: 0 | I22: DEFAULT | J22: =Sheet1!$D$46 -> 0 | K22: =Sheet1!$D$45 -> 0.32 | L22: 1,0,0,2,23,24,6,0,0 | M22: 0 | O22: =Sheet1!$E$45 -> Technical success/failure | P22: FALSE
A23: =Sheet1!$F$6 -> 125 | B23: Success | C23: 0 | H23: DEFAULT | I23: DEFAULT | J23: =Sheet1!$E$6 -> 125 | K23: =Sheet1!$E$5 -> 0.85 | L23: 4,0,0,0,7,0,0 | M23: 0 | P23: FALSE
A24: =Sheet1!$F$10 -> -15 | B24: Failure | C24: 0 | H24: DEFAULT | I24: DEFAULT | J24: =Sheet1!$E$10 -> -15 | K24: =Sheet1!$E$9 -> 0.15 | L24: 4,0,0,0,7,0,0 | M24: 0 | P24: FALSE
A25: =Sheet1!$F$14 -> -15 | B25: Success | C25: 0 | H25: DEFAULT | I25: DEFAULT | J25: =Sheet1!$E$14 -> -15 | K25: =Sheet1!$E$13 -> 0.85 | L25: 4,0,0,0,8,0,0 | M25: 0 | P25: FALSE
A26: =Sheet1!$F$18 -> -15 | B26: Failure | C26: 0 | H26: DEFAULT | I26: DEFAULT | J26: =Sheet1!$E$18 -> -15 | K26: =Sheet1!$E$17 -> 0.15 | L26: 4,0,0,0,8,0,0 | M26: 0 | P26: FALSE
A27: =Sheet1!$F$22 -> 100 | B27: Success | C27: 0 | H27: DEFAULT | I27: DEFAULT | J27: =Sheet1!$E$22 -> 100 | K27: =Sheet1!$E$21 -> 0.85 | L27: 4,0,0,0,9,0,0 | M27: 0 | P27: FALSE
A28: =Sheet1!$F$26 -> -18 | B28: Failure | C28: 0 | H28: DEFAULT | I28: DEFAULT | J28: =Sheet1!$E$26 -> -18 | K28: =Sheet1!$E$25 -> 0.15 | L28: 4,0,0,0,9,0,0 | M28: 0 | P28: FALSE
A29: =Sheet1!$F$30 -> -18 | B29: Success | C29: 0 | H29: DEFAULT | I29: DEFAULT | J29: =Sheet1!$E$30 -> -18 | K29: =Sheet1!$E$29 -> 0.85 | L29: 4,0,0,0,10,0,0 | M29: 0 | P29: FALSE
A30: =Sheet1!$F$34 -> -18 | B30: Failure | C30: 0 | H30: DEFAULT | I30: DEFAULT | J30: =Sheet1!$E$34 -> -18 | K30: =Sheet1!$E$33 -> 0.15 | L30: 4,0,0,0,10,0,0 | M30: 0 | P30: FALSE
A31: =Sheet1!$F$36 -> 75 | B31: Success | C31: 0 | H31: DEFAULT | I31: DEFAULT | J31: =Sheet1!$E$36 -> 75 | K31: =Sheet1!$E$35 -> 0.85 | L31: 4,0,0,0,11,0,0 | M31: 0 | P31: FALSE
A32: =Sheet1!$F$40 -> -23 | B32: Failure | C32: 0 | H32: DEFAULT | I32: DEFAULT | J32: =Sheet1!$E$40 -> -23 | K32: =Sheet1!$E$39 -> 0.15 | L32: 4,0,0,0,11,0,0 | M32: 0 | P32: FALSE
A33: =Sheet1!$F$44 -> -23 | B33: Success | C33: 0 | H33: DEFAULT | I33: DEFAULT | J33: =Sheet1!$E$44 -> -23 | K33: =Sheet1!$E$43 -> 0.85 | L33: 4,0,0,0,12,0,0 | M33: 0 | P33: FALSE
A34: =Sheet1!$F$48 -> -23 | B34: Failure | C34: 0 | H34: DEFAULT | I34: DEFAULT | J34: =Sheet1!$E$48 -> -23 | K34: =Sheet1!$E$47 -> 0.15 | L34: 4,0,0,0,12,0,0 | M34: 0 | P34: FALSE
